Workbook

Sheet 0) SL Project Structure
A1: SL Project Services Functional Strategy Project Landscape Map (Coded by Principle Current Commercial Delivery Framework) (Projects with Lifecycle Forecast over £20M)
A2: Total Lifetime EAC Value of SL Projects over £20M = | G2: =I5+P5+W5+AK5+P56 -> 9662.5718
D4: Project Delivery Directorate (PDD) | K4: Remediation | R4: Retrievals | AC4: Site Project Office
D5: Director / Lead: A. Sharples | G5: Lifecycle Value: | I5: =C15+C21+C27+C33+C39+C45+C51+G15+G21+G27+G33 -> 6641.1444 | K5: Director / Lead: G. McCracken | N5: Lifecycle Value: | P5: =L15+L21+L27+L33 -> 328.098 | R5: Director / Lead: J. Millington | S5: C. Carruthers | U5: Lifecycle Value: | W5: =S15+S21+S27+S33+S39+S45+S51 -> 1604.5912 | AC5: Director / Lead: M. Johns | AI5: Lifecycle Value: | AK5: =AD9+AD28+AD46+AL9 -> 1061.8363
D6: PC Lead: Lee Edgar & SPCMs | K6: PC Lead: A Grainger | R6: PC Lead: Programme PCMs | AC6: PC Lead: J Irving
Y8: Categorised / Value Streams | AG8: Infrastructure
D9: PPP | H9: Legacy | Y9: Director / Lead: J. Brocklebank | AB9: Lifecycle Value: | AD9: =+Z17+Z24 -> 63.090549 | AG9: Director / Lead: C. Mills | AJ9: Lifecycle Value: | AL9: =+AH17+AH24+AH31+AH38+AH45+AH52+AH59 -> 717.26252
R10: N.B. Project very close to completion | AG10: PC Lead: S Jackson
B11: Proj No: | C11: 35/09592 | F11: Proj No: | G11: 35/10137 | K11: Proj No: | L11: 35/05396 | R11: Proj No: | S11: 35/10095
B12: Programme: | C12: SNM Future State | F12: Programme: | G12: Magnox Swarf Storage Silo | K12: Programme: | L12: *1 - Final Decommissioning | R12: Programme: | S12: Pile Fuel Cladding Silo
B13: Title: | C13: Sellafield Product & Residue Store Retreatment Plant | F13: Title: | G13: Box Encapsulation Plant | K13: Title: | L13: Chimney Decommissioning Phase 2F | R13: Title: | S13: Box Encapsulation Plant Product Store Direct Import Facility | Y13: Proj No: | Z13: 35/10188 | AG13: Proj No: | AH13: 35/09140
B14: SRO | C14: Jeremy Hunt | F14: SPA | G14: Phil Reeve | K14: SPA | L14: Glenn McCracken | R14: SPA | S14: Kevin Brown | Y14: Programme: | Z14: AGROP | AG14: Programme: | AH14: Utilities and Future Energy
B15: Lifecycle P50: | C15: =VLOOKUP(C13,'5a)NDA MPPR'!$B$9:$AK$61,21,FALSE) -> 1466.5527 | F15: Lifecycle P50: | G15: =VLOOKUP(G13,'5a)NDA MPPR'!$B$9:$AK$61,21,FALSE) -> 1445.0751 | K15: Lifecycle P50: | L15: =VLOOKUP(L13,'5a)NDA MPPR'!$B$9:$AK$61,21,FALSE) -> 148.90141 | R15: Lifecycle P50: | S15: =VLOOKUP(S13,'5a)NDA MPPR'!$B$9:$AK$61,21,FALSE) -> 458.24396 | Y15: Title: | Z15: THORP Receipt & Storage Control Systems Replacement | AG15: Title: | AH15: Electrical Supply - New Construction
Y16: SPA | Z16: Andrew Pringle | AG16: SRO | AH16: Gavin Askew
B17: Proj No: | C17: 35/09343 | F17: Proj No: | G17: 35/09975 | K17: Proj No: | L17: 35/09707 | R17: Proj No: | S17: 35/06075 | Y17: Lifecycle P50: | Z17: =VLOOKUP(Z15,'4b) SL EPO Extended Data Sheet'!$A$5:$AB$176,17,FALSE)/1000000 -> 23.356291 | AG17: Lifecycle P50: | AH17: =VLOOKUP(AH15,'5a)NDA MPPR'!$B$9:$AK$61,21,FALSE) -> 427.81347
B18: Programme: | C18: SIXEP Capability | F18: Programme: | G18: Unified Command & Control | K18: Programme: | L18: *1 - Final Decommissioning | R18: Programme: | S18: Magnox Swarf Storage Silo | AG18: Infrastructure
B19: Title: | C19: SIXEP Continuity Plant | F19: Title: | G19: Security Systems Architecture Upgrade (SSAU) | K19: Title: | L19: LAETP Floc Retrieval | R19: Title: | S19: SEP Solid Waste Storage Retrievals
B20: SRO | C20: Jeremy Hunt | F20: SPA | G20: Michael Askew | K20: SPA | L20: Glenn McCracken | R20: SPA | S20: Phil Reeve | Y20: Proj No: | Z20: 35/10151 | AG20: Proj No: | AH20: 35/10565
B21: Lifecycle P50: | C21: =VLOOKUP(C19,'5a)NDA MPPR'!$B$9:$AK$61,21,FALSE) -> 1120.8757 | F21: Lifecycle P50: | G21: =VLOOKUP(G19,'5a)NDA MPPR'!$B$9:$AK$61,21,FALSE) -> 315.08361 | K21: Lifecycle P50: | L21: =VLOOKUP(L19,'5a)NDA MPPR'!$B$9:$AK$61,21,FALSE) -> 87.561965 | R21: Lifecycle P50: | S21: =VLOOKUP(S19,'5a)NDA MPPR'!$B$9:$AK$61,21,FALSE) -> 887.19569 | Y21: Programme: | Z21: No Programme | AG21: Programme: | AH21: No Programme
Y22: Title: | Z22: FHP & SIXEP Roof Replacement | AG22: Title: | AH22: EMRMS (Emergency Management Radiological Monitoring System)
B23: Proj No: | C23: 35/07654 | F23: Proj No: | G23: 35/09968 | K23: Proj No: | L23: 35/09000 | R23: Proj No: | S23: 35/05684 | Y23: SPA | Z23: Stuart Pearson | AG23: SPA | AH23: Rob Hargreaves
B24: Programme: | C24: Retrievals Value Stream Waste Capabilities | F24: Programme: | G24: Unified Command & Control | K24: Programme: | L24: *1 - Final Decommissioning | R24: Programme: | S24: Magnox Swarf Storage Silo | Y24: Lifecycle P50: | Z24: =VLOOKUP(Z22,'4b) SL EPO Extended Data Sheet'!$A$5:$AB$176,17,FALSE)/1000000 -> 39.734258 | AG24: Lifecycle P50: | AH24: =VLOOKUP(AH22,'4b) SL EPO Extended Data Sheet'!$A$5:$AB$176,17,FALSE)/1000000 -> 32.00067
B25: Title: | C25: BEPPS2 | F25: Title: | G25: CNC Operational Unit | K25: Title: | L25: Heat Exchanger Deplanting - Main Project | R25: Title: | S25: MSSS Upgrades for Retrievals & Resilience | AG25: Analytical Services
B26: SRO | C26: Kathryn McCloghrie | F26: SPA | G26: Michael Askew | K26: SPA | L26: Glenn McCracken | R26: SPA | S26: Phil Reeve
B27: Lifecycle P50: | C27: =VLOOKUP(C25,'5a)NDA MPPR'!$B$9:$AK$61,21,FALSE) -> 749.16803 | F27: Lifecycle P50: | G27: =VLOOKUP(G25,'5a)NDA MPPR'!$B$9:$AK$61,21,FALSE) -> 71.079063 | K27: Lifecycle P50: | L27: =VLOOKUP(L25,'5a)NDA MPPR'!$B$9:$AK$61,21,FALSE) -> 53.218374 | R27: Lifecycle P50: | S27: =VLOOKUP(S25,'4b) SL EPO Extended Data Sheet'!$A$5:$AB$176,17,FALSE)/1000000 -> 101.98066 | Y27: Special Nuclear Materials (SNM) | AG27: Proj No: | AH27: 35/10475
Y28: Director / Lead: P. Nichol | AB28: Lifecycle Value: | AD28: =Z35+Z42 -> 122.47097 | AG28: Programme: | AH28: Land and Infrastructure Future State
B29: Proj No: | C29: 35/09203 | F29: Proj No: | G29: 35/09976 | K29: Proj No: | L29: 35/10398 | R29: Proj No: | S29: 35/10242 | AG29: Title: | AH29: Product Zone Power Supply
B30: Programme: | C30: Decommissioning Higher Active Waste Capability (DHAWC) | F30: Programme: | G30: Unified Command & Control | K30: Programme: | L30: *1 - Final Decommissioning | R30: Programme: | S30: Pile Fuel Cladding Silo | AG30: SRO | AH30: Gavin Askew
B31: Title: | C31: Lightly Shielded Store (LSS) | F31: Title: | G31: Enhanced CNC Airwave System (Encrypted Comms) | K31: Title: | L31: Calder Land Clearance | R31: Title: | S31: PFCS Full Retrievals - Project 1 | Y31: Proj No: | Z31: 35/09244 | AG31: Lifecycle P50: | AH31: =VLOOKUP(AH29,'4b) SL EPO Extended Data Sheet'!$A$5:$AB$176,17,FALSE)/1000000 -> 82.916699
B32: SRO | C32: Kathryn McCloghrie | F32: SPA | G32: Michael Askew | K32: SPA | L32: Jeremy Hunt | R32: SPA | S32: Kevin Brown | Y32: Programme: | Z32: SNM Future State
B33: Lifecycle P50: | C33: =VLOOKUP(C31,'4b) SL EPO Extended Data Sheet'!$A$5:$AB$176,17,FALSE)/1000000 -> 157.94101 | F33: Lifecycle P50: | G33: =VLOOKUP(G31,'5a)NDA MPPR'!$B$9:$AK$61,21,FALSE) -> 18.769073 | K33: Lifecycle P50: | L33: =VLOOKUP(L31,'4b) SL EPO Extended Data Sheet'!$A$5:$AB$176,17,FALSE)/1000000 -> 38.416249 | R33: Lifecycle P50: | S33: =VLOOKUP(S31,'5a)NDA MPPR'!$B$9:$AK$61,21,FALSE) -> 72.459952 | Y33: Title: | Z33: FGFL Ventilation Extract System Upgrade
F34: N.B. Project paused | K34: N.B *1 - Final Decommissioning OU is not a programme in the new construct | Y34: SPA | Z34: Simon Bremer | AG34: Proj No: | AH34: 35/10545
B35: Proj No: | C35: 35/10371 | R35: Proj No: | S35: 35/09198 | Y35: Lifecycle P50: | Z35: =VLOOKUP(Z33,'4b) SL EPO Extended Data Sheet'!$A$5:$AB$176,17,FALSE)/1000000 -> 84.193985 | AG35: Programme: | AH35: No Programme
B36: Programme: | C36: First Generation Magnox Storage Pond | R36: Programme: | S36: Pile Fuel Cladding Silo | AG36: Title: | AH36: Degradation of Pipebridge 57 (PB57) L14, L15, L16 Refurbishment
B37: Title: | C37: Sludge Handling & Export Plant | R37: Title: | S37: Sellafield 3m3 Box Supply - Tranche A | AG37: SPA | AH37: Stuart Latham
B38: SPA | C38: Carl Carruthers | R38: SPA | S38: Kevin Brown | Y38: Proj No: | Z38: 35/09357 | AG38: Lifecycle P50: | AH38: =VLOOKUP(AH36,'4b) SL EPO Extended Data Sheet'!$A$5:$AB$176,17,FALSE)/1000000 -> 31.203278
B39: Lifecycle P50: | C39: =VLOOKUP(C37,'4b) SL EPO Extended Data Sheet'!$A$5:$AB$176,17,FALSE)/1000000 -> 341.04335 | R39: Lifecycle P50: | S39: =VLOOKUP(S37,'4b) SL EPO Extended Data Sheet'!$A$5:$AB$176,17,FALSE)/1000000 -> 36.17178 | Y39: Programme: | Z39: SNM Future State | AG39: Utilites | AO39: Principle Project Commercial Delivery Framework Key
Y40: Title: | Z40: PMF North Transfers Project
B41: Proj No: | C41: 35/10417 | R41: Proj No: | S41: 35/10342 | Y41: SRO SPA | Z41: Jeremy Hunt Paul Nichol | AG41: Proj No: | AH41: 35/09248 | AQ41: Programme and Project Partners (PPP)
B42: Programme: | C42: Land and Infrastructure Future State | R42: Programme: | S42: Magnox Swarf Storage Silos | Y42: Lifecycle P50: | Z42: =VLOOKUP(Z40,'4b) SL EPO Extended Data Sheet'!$A$5:$AB$176,17,FALSE)/1000000 -> 38.276981 | AG42: Programme: | AH42: Utilities and Future Energy
...

Sheet 0) SL Project Structure OLD
A1: SL Project Services Functional Strategy Project Landscape Map (Coded by Principle Current Commercial Delivery Framework) (Projects with Lifecycle Forecast over £20M)
A2: Total Lifetime EAC Value of SL Projects over £20M = | G2: =I5+P5+W5+AH5+P53 -> #N/A
D4: Project Delivery Directorate (PDD) | K4: Remediation | R4: Retrievals | AC4: Site Management Projects (SMPro)
D5: Director / Lead: A. Sharples | G5: Lifecycle Value: | I5: =C14+C19+C24+C29+C34+C39+C44+C49+G14+G19+G24+G29 -> #N/A | K5: Director / Lead: G. McCracken | N5: Lifecycle Value: | P5: =L14+L19+L24+L29+L34+L39 -> #N/A | R5: Director / Lead: A. Armett | U5: Lifecycle Value: | W5: =S14+S19+S24+S29+S34+S39+S44+S49 -> #N/A | AC5: Director / Lead: M. Johns | AF5: Lifecycle Value: | AH5: =AD9+AD47+AD60+AL9 -> #N/A
D6: PC Lead: Lee Edgar & SPCMs | K6: PC Lead: A Grainger | R6: PC Lead: J Kolbe | AC6: PC Lead: J Irving
Y8: Site Management | AG8: Infrastructure
D9: PPP | H9: Legacy | Y9: Director / Lead: J. Brocklebank | AB9: Lifecycle Value: | AD9: =Z14+Z19+Z24+Z29+Z34+Z39+Z44 -> 676.02499 | AG9: Director / Lead: C. Mills | AJ9: Lifecycle Value: | AL9: =AH16+AH22+AH28 -> #N/A
R10: N.B. Project very close to completion | AG10: PC Lead: S Jackson
B11: Proj No: | C11: 35/09592 | F11: Proj No: | G11: 35/10137 | K11: Proj No: | L11: 35/05396 | R11: Proj No: | S11: 35/10095 | Y11: Proj No: | Z11: 35/09140
B12: Title: | C12: Sellafield Product & Residue Store Retreatment Plant | F12: Title: | G12: Box Encapsulation Plant | K12: Title: | L12: Chimney Decommissioning Phase 2F | R12: Title: | S12: Box Encapsulation Plant Product Store Direct Import Facility | Y12: Title: | Z12: Electrical Supply - New Construction | AG12: Infrastructure
B13: SRO | C13: Jeremy Hunt | F13: SPA | G13: Phil Reeve | K13: SPA | L13: Glenn McCracken | R13: SPA | S13: Kevin Brown | Y13: SRO | Z13: Gavin Askew | AG13: Proj No: | AH13: 35/10565
B14: Lifecycle P50: | C14: =VLOOKUP(C12,'5a)NDA MPPR'!$B$9:$AK$61,21,FALSE) -> 1466.5527 | F14: Lifecycle P50: | G14: =VLOOKUP(G12,'5a)NDA MPPR'!$B$9:$AK$61,21,FALSE) -> 1445.0751 | K14: Lifecycle P50: | L14: =VLOOKUP(L12,'5a)NDA MPPR'!$B$9:$AK$61,21,FALSE) -> 148.90141 | R14: Lifecycle P50: | S14: =VLOOKUP(S12,'5a)NDA MPPR'!$B$9:$AK$61,21,FALSE) -> 458.24396 | Y14: Lifecycle P50: | Z14: =VLOOKUP(Z12,'5a)NDA MPPR'!$B$9:$AK$61,21,FALSE) -> 427.81347 | AG14: Title: | AH14: EMRMS (Emergency Management Radiological Monitoring System)
AG15: SPA | AH15: Rob Hargreaves
B16: Proj No: | C16: 35/09343 | F16: Proj No: | G16: 35/09975 | K16: Proj No: | L16: 35/09707 | R16: Proj No: | S16: 35/06075 | Y16: Proj No: | Z16: 35/10188 | AG16: Lifecycle P50: | AH16: =VLOOKUP(AH14,'4b) SL EPO Extended Data Sheet'!$A$5:$AB$176,16,FALSE)/1000000 -> 32.152519
B17: Title: | C17: SIXEP Continuity Plant | F17: Title: | G17: Security Systems Architecture Upgrade (SSAU) | K17: Title: | L17: LAETP Floc Retrieval | R17: Title: | S17: SEP Solid Waste Storage Retrievals | Y17: Title: | Z17: THORP Receipt & Storage Control Systems Replacement
B18: SRO | C18: Jeremy Hunt | F18: SPA | G18: Michael Askew | K18: SPA | L18: Glenn McCracken | R18: SPA | S18: Phil Reeve | Y18: SPA | Z18: Andrew Pringle | AG18: Utilites
B19: Lifecycle P50: | C19: =VLOOKUP(C17,'5a)NDA MPPR'!$B$9:$AK$61,21,FALSE) -> 1120.8757 | F19: Lifecycle P50: | G19: =VLOOKUP(G17,'5a)NDA MPPR'!$B$9:$AK$61,21,FALSE) -> 315.08361 | K19: Lifecycle P50: | L19: =VLOOKUP(L17,'5a)NDA MPPR'!$B$9:$AK$61,21,FALSE) -> 87.561965 | R19: Lifecycle P50: | S19: =VLOOKUP(S17,'5a)NDA MPPR'!$B$9:$AK$61,21,FALSE) -> 887.19569 | Y19: Lifecycle P50: | Z19: =VLOOKUP(Z17,'4b) SL EPO Extended Data Sheet'!$A$5:$AB$176,16,FALSE)/1000000 -> 20.914989 | AG19: Proj No: | AH19: 35/09248
AG20: Title: | AH20: Substations 6 & 7 Replacement
B21: Proj No: | C21: 35/09269 | F21: Proj No: | G21: 35/09968 | K21: Proj No: | L21: 35/09000 | R21: Proj No: | S21: 35/05684 | Y21: Proj No: | Z21: 35/10151 | AG21: SRO | AH21: Gavin Askew
B22: Title: | C22: Replacement Analytical Project | F22: Title: | G22: CNC Operational Unit | K22: Title: | L22: Heat Exchanger Deplanting - Main Project | R22: Title: | S22: MSSS Upgrades for Retrievals & Resilience | Y22: Title: | Z22: FHP & SIXEP Roof Replacement | AG22: Lifecycle P50: | AH22: =VLOOKUP(AH20,'4b) SL EPO Extended Data Sheet'!$A$5:$AB$176,16,FALSE)/1000000 -> 64.421715
B23: SRO | C23: Gavin Askew | F23: SPA | G23: Michael Askew | K23: SPA | L23: Glenn McCracken | R23: SPA | S23: Phil Reeve | Y23: SPA | Z23: Stuart Pearson
B24: Lifecycle P50: | C24: =VLOOKUP(C22,'5a)NDA MPPR'!$B$9:$AK$61,21,FALSE) -> #N/A | F24: Lifecycle P50: | G24: =VLOOKUP(G22,'5a)NDA MPPR'!$B$9:$AK$61,21,FALSE) -> 71.079063 | K24: Lifecycle P50: | L24: =VLOOKUP(L22,'5a)NDA MPPR'!$B$9:$AK$61,21,FALSE) -> 53.218374 | R24: Lifecycle P50: | S24: =VLOOKUP(S22,'4b) SL EPO Extended Data Sheet'!$A$5:$AB$176,16,FALSE)/1000000 -> 103.81815 | Y24: Lifecycle P50: | Z24: =VLOOKUP(Z22,'4b) SL EPO Extended Data Sheet'!$A$5:$AB$176,16,FALSE)/1000000 -> 26.545167 | AG24: Analytical Services
B25: N.B. Project paused | AG25: Proj No: | AH25: 35/10523
B26: Proj No: | C26: 35/07654 | F26: Proj No: | G26: 35/09976 | K26: Proj No: | L26: 35/10398 | R26: Proj No: | S26: 35/10242 | Y26: Proj No: | Z26: 35/10475 | AG26: Title: | AH26: Sample Management Capability
B27: Title: | C27: BEPPS2 | F27: Title: | G27: Enhanced CNC Airwave System (Encrypted Comms) | K27: Title: | L27: Calder Land Clearance | R27: Title: | S27: PFCS Full Retrievals - Project 1 | Y27: Title: | Z27: Product Zone Power Supply | AG27: SRO | AH27: Gavin Askew
B28: SRO | C28: Kathryn McCloghrie | F28: SPA | G28: Michael Askew | K28: SPA | L28: Jeremy Hunt | R28: SPA | S28: Kevin Brown | Y28: SRO | Z28: Gavin Askew | AG28: Lifecycle P50: | AH28: =VLOOKUP(AH26,'4b) SL EPO Extended Data Sheet'!$A$5:$AB$176,16,FALSE)/1000000 -> #N/A
B29: Lifecycle P50: | C29: =VLOOKUP(C27,'5a)NDA MPPR'!$B$9:$AK$61,21,FALSE) -> 749.16803 | F29: Lifecycle P50: | G29: =VLOOKUP(G27,'5a)NDA MPPR'!$B$9:$AK$61,21,FALSE) -> 18.769073 | K29: Lifecycle P50: | L29: =VLOOKUP(L27,'4b) SL EPO Extended Data Sheet'!$A$5:$AB$176,16,FALSE)/1000000 -> 38.593832 | R29: Lifecycle P50: | S29: =VLOOKUP(S27,'5a)NDA MPPR'!$B$9:$AK$61,21,FALSE) -> 72.459952 | Y29: Lifecycle P50: | Z29: =VLOOKUP(Z27,'4b) SL EPO Extended Data Sheet'!$A$5:$AB$176,16,FALSE)/1000000 -> 84.328299
F30: N.B. Project paused
B31: Proj No: | C31: 35/09203 | K31: Proj No: | L31: 35/10401 | R31: Proj No: | S31: 35/09198 | Y31: Proj No: | Z31: 35/10545 | AG31: Principle Project Commercial Delivery Framework Key
B32: Title: | C32: Lightly Shielded Store (LSS) | K32: Title: | L32: Decommissioning Encapsulation Plant | R32: Title: | S32: Sellafield 3m3 Box Supply - Tranche A | Y32: Title: | Z32: Degradation of Pipebridge 57 (PB57) L14, L15, L16 Refurbishment
B33: SRO | C33: Kathryn McCloghrie | K33: SRO | L33: Kathryn McCloghrie | R33: SPA | S33: Kevin Brown | Y33: SPA | Z33: Stuart Latham | AH33: Programme and Project Partners (PPP)
B34: Lifecycle P50: | C34: =VLOOKUP(C32,'4b) SL EPO Extended Data Sheet'!$A$5:$AB$176,16,FALSE)/1000000 -> 142.42994 | K34: Lifecycle P50: | L34: =VLOOKUP(L32,'4b) SL EPO Extended Data Sheet'!$A$5:$AB$176,16,FALSE)/1000000 -> #N/A | R34: Lifecycle P50: | S34: =VLOOKUP(S32,'4b) SL EPO Extended Data Sheet'!$A$5:$AB$176,16,FALSE)/1000000 -> 74.471369 | Y34: Lifecycle P50: | Z34: =VLOOKUP(Z32,'4b) SL EPO Extended Data Sheet'!$A$5:$AB$176,16,FALSE)/1000000 -> 30.826939
AH35: Legacy Bespoke Contracts (ie. BEP JV)
B36: Proj No: | C36: 35/10371 | K36: Proj No: | L36: 35/10402 | R36: Proj No: | S36: 35/10128 | Y36: Proj No: | Z36: 35/10563
B37: Title: | C37: Sludge Handling & Export Plant | K37: Title: | L37: Remote Handlable Intermediate Level Waste (RHILW) | R37: Title: | S37: Self Shielded Boxes Design and Manufacture | Y37: Title: | Z37: Substation 10 Replacement | AH37: Decommissioning Delivery Partner (DDP)
B38: SPA | C38: Carl Carruthers | K38: SRO | L38: Kathryn McCloghrie | R38: SPA | S38: Carl Carruthers | Y38: SRO | Z38: Gavin Askew
B39: Lifecycle P50: | C39: =VLOOKUP(C37,'4b) SL EPO Extended Data Sheet'!$A$5:$AB$176,16,FALSE)/1000000 -> 340 | K39: Lifecycle P50: | L39: =VLOOKUP(L37,'4b) SL EPO Extended Data Sheet'!$A$5:$AB$176,16,FALSE)/1000000 -> #N/A | R39: Lifecycle P50: | S39: =VLOOKUP(S37,'4b) SL EPO Extended Data Sheet'!$A$5:$AB$176,16,FALSE)/1000000 -> #N/A | Y39: Lifecycle P50: | Z39: =VLOOKUP(Z37,'4b) SL EPO Extended Data Sheet'!$A$5:$AB$176,16,FALSE)/1000000 -> 42.841254 | AH39: Design Services Alliance (DSA)
B41: Proj No: | C41: 35/10417 | R41: Proj No: | S41: 35/10342 | Y41: Proj No: | Z41: 35/10564 | AH41: Infrastructure Services Alliance (ISA)
B42: Title: | C42: ILW East Land Excavation | R42: Title: | S42: MSSS SEP3 Rails & Brackets | Y42: Title: | Z42: Substation 15 Replacement
B43: SPA | C43: Gavin Askew | R43: SPA | S43: Phil Reeve | Y43: SRO | Z43: Gavin Askew
...

Sheet 1) Report
B3: Project Number | C3: Project Name | D3: Occom | F3: Approved Business Case and Sanction | R3: Baseline | AM3: Capability and Capacity | AO3: DCA Comparison | AS3: Baseline RAG Comparison | AV3: Previous Period Data for Variance Calcs | AY3: Changes to Current Baseline (P50)
F4: Delivery Confidence Assessment (DCA) | I4: Approved Business Case | O4: Sanction | R4: Baseline RAG | U4: Current Baseline in Effect From | W4: Whole Life | AE4: Cumulative vs. Current Baseline
I5: Business Case Approval Date | J5: Project Cost | L5: Project End Date | O5: Sanction Approved to NDA | P5: Sanction Released to OpCo | W5: Project Cost | AA5: Project End Date | AE5: Budgeted Cost Work Scheduled (BCWS) | AF5: Budgeted Cost Work Performed (BCWP) | AG5: Actual Cost Work Performed (ACWP) | AH5: Cost Perf. Index (CPI) | AI5: Schedule Perf. Index (SPI) | AJ5: % Complete | AO5: EAC vs. Approved BC WLC (P80) | AP5: EAC vs. Sanction Approved to NDA (P80) | AQ5: Forecast End Date vs. Approved BC (P80) | AS5: EAC vs. Current Baseline (P50) | AT5: Forecast End Date vs. Current Baseline (P50) | AV5: Cost | AW5: End Date | AY5: Project Cost | BA5: Project End Date
J6: Business Case (P50) | K6: Business Case (P80) | L6: Business Case (P50) | M6: Business Case (P80) | W6: Current Baseline (P50) | X6: Estimate At Complete (EAC) | Y6: EAC vs. Last Period | AA6: Current Baseline (P50) | AB6: Forecast | AC6: Forecast vs. Last Period (Days) | AJ6: Plan | AK6: Actual | AV6: EAC Last Period | AW6: Forecast Last Period | AY6: Baseline (P50) Last Period | AZ6: Change to Baseline (P50) | BA6: Baseline (P50) Last Period | BB6: Change to Baseline (P50)
B8: Security & Resilience
B10: Portfolio Summary
B11: n/a | C11: Sellafield Security Enhancement Programme (SSEP) | D11: Sellafield | F11: =VLOOKUP(C11,'5a)NDA MPPR'!$B$9:$AK$61,3,FALSE) -> G | G11: =VLOOKUP(C11,'5a)NDA MPPR'!$B$9:$AK$61,4,FALSE) -> 0 | I11: =VLOOKUP(C11,'5a)NDA MPPR'!$B$9:$AK$61,6,FALSE) -> PBC (Jun-24) | J11: =VLOOKUP(C11,'5a)NDA MPPR'!$B$9:$AK$61,7,FALSE) -> 904 | K11: =VLOOKUP(C11,'5a)NDA MPPR'!$B$9:$AK$61,8,FALSE) -> 921.8 | L11: =VLOOKUP(C11,'5a)NDA MPPR'!$B$9:$AK$61,9,FALSE) -> 46022 | M11: =VLOOKUP(C11,'5a)NDA MPPR'!$B$9:$AK$61,10,FALSE) -> 46234 | O11: =VLOOKUP(C11,'5a)NDA MPPR'!$B$9:$AK$61,12,FALSE) -> 921.8 | P11: =VLOOKUP(C11,'5a)NDA MPPR'!$B$9:$AK$61,13,FALSE) -> 921.8 | R11: =VLOOKUP(C11,'5a)NDA MPPR'!$B$9:$AK$61,15,FALSE) -> N/A | S11: =VLOOKUP(C11,'5a)NDA MPPR'!$B$9:$AK$61,16,FALSE) -> 0 | U11: =VLOOKUP(C11,'5a)NDA MPPR'!$B$9:$AK$61,18,FALSE) -> PBC (Oct-21) | W11: =VLOOKUP(C11,'5a)NDA MPPR'!$B$9:$AK$61,20,FALSE) -> - | X11: =VLOOKUP(C11,'5a)NDA MPPR'!$B$9:$AK$61,21,FALSE) -> 914.56678 | Y11: =VLOOKUP(C11,'5a)NDA MPPR'!$B$9:$AK$61,22,FALSE) -> -6.9 | AA11: =VLOOKUP(C11,'5a)NDA MPPR'!$B$9:$AK$61,24,FALSE) -> - | AB11: =VLOOKUP(C11,'5a)NDA MPPR'!$B$9:$AK$61,25,FALSE) -> 46234 | AC11: =VLOOKUP(C11,'5a)NDA MPPR'!$B$9:$AK$61,26,FALSE) -> 0 | AE11: =VLOOKUP(C11,'5a)NDA MPPR'!$B$9:$AK$61,28,FALSE) -> 0 | AF11: =VLOOKUP(C11,'5a)NDA MPPR'!$B$9:$AK$61,29,FALSE) -> 0 | AG11: =VLOOKUP(C11,'5a)NDA MPPR'!$B$9:$AK$61,30,FALSE) -> 909.09983 | AH11: =VLOOKUP(C11,'5a)NDA MPPR'!$B$9:$AK$61,31,FALSE) -> 0 | AI11: =VLOOKUP(C11,'5a)NDA MPPR'!$B$9:$AK$61,32,FALSE) -> 0 | AJ11: =VLOOKUP(C11,'5a)NDA MPPR'!$B$9:$AK$61,33,FALSE) -> 0 | AK11: =VLOOKUP(C11,'5a)NDA MPPR'!$B$9:$AK$61,34,FALSE) -> 0 | AM11: =VLOOKUP(C11,'5a)NDA MPPR'!$B$9:$AK$61,36,FALSE) -> N/A | AV11: 921.42523 | AW11: 46234 | AY11: 0 | BA11: -
A12: =C11 -> Sellafield Security Enhancement Programme (SSEP) | B12: =VLOOKUP($C11,'5a)NDA MPPR'!$A$9:$AK$61,2,FALSE) -> The Sellafield Security Enhancement Programme (SSEP) represents a series of interdependent security enhancement projects, which encompass site-wide improvement initiatives, and some facility-specific asset improvements. The Delivery Confidence Assessment remains Green. The NDA revised Programme Business Case value of £921.8m was released to SL in June 2024, with Department for Energy Security and Net Zero (DESNZ) PIC holding the upper range figure of £929.8m. The SSAU and CNC OU P80 sanction request submissions were approved at the NDA Group Investment Committee (GIC) in September 2024. The assessment work on Encrypted Comms project is complete resulting in a significant reduction in the project scope. The project EAC has therefore been reduced accordingly. Formal governance steps will conclude during period 8. The programme lifecycle EAC has therefore been reduced to reflect the EC position. The Programme Ready for FOC, based on the latest SSAU project data, remains forecast as March 2026 due to delays to the progression of the Legacy SMS migrations, which are scheduled to take place after the L1 commissioning of the new boundaries.. This is subject to ongoing reviews of the available operational, engineering and maintenance resources needed to review and sign off the various systems and assets being delivered by the projects to underpin the Custody Transfer Certificate (CTC). The overall outturn project delivery performance remains in line with sanctioned plans. Security Systems Architecture Upgrade (SSAU), Encrypted Comms (EC) & Civil Nuclear Constabulary (CNC) Operational Unit (CNC OU) Projects (all reported as projects in their own right on the MPPR) are, based on the respective projects latest EAC figures, affordable within the released SSEP sanction. The Main Site Command Facility (MSCF) continues to improve its operational capability with Phases 1 & 2 of the revised 3 Phase Capability Delivery Plan now complete. (Phase 1: The High Security Area (HSA)1 Boundary declared operational in March 2024 & Phase 2: The achievement of a Green rating for the complex and challenging Level 1 Regulator Evaluated Demonstration Exercise in November 2024). As a consequence the Regulator confirmed in December 2024, Physical Security no longer needs to be monitored at the “Enhanced Level” and has therefore been returned to “Routine Level” with the Nuclear Site Security Plan (NSSP) and Security Improvement Schedule (SIS) updated accordingly; a significant achievement for the Sellafield Site. Phase 3 will achieve the agreed security outcomes and associated security risk reduction benefits by no later than May 2027 for Full Operating Capability (FOC). The latest programme forecast aligns with the current CNC OU P80 sanction date of 31 July 2026. The programme remains within its sanctioned tolerances.
B14: Project Delivery Directorate
B16: Portfolio Summary
B17: 35/09976 | C17: Enhanced CNC Airwave System (Encrypted Comms) | D17: Sellafield | F17: =VLOOKUP(C17,'5a)NDA MPPR'!$B$9:$AK$61,3,FALSE) -> R | G17: =VLOOKUP(C17,'5a)NDA MPPR'!$B$9:$AK$61,4,FALSE) -> 0 | I17: =VLOOKUP(C17,'5a)NDA MPPR'!$B$9:$AK$61,6,FALSE) -> OBC (Mar-20) | J17: =VLOOKUP(C17,'5a)NDA MPPR'!$B$9:$AK$61,7,FALSE) -> 25.838 | K17: =VLOOKUP(C17,'5a)NDA MPPR'!$B$9:$AK$61,8,FALSE) -> 31.94 | L17: =VLOOKUP(C17,'5a)NDA MPPR'!$B$9:$AK$61,9,FALSE) -> 45058 | M17: =VLOOKUP(C17,'5a)NDA MPPR'!$B$9:$AK$61,10,FALSE) -> 45412 | N17: ='3) BC and Sanction'!I94 -> 0 | O17: =VLOOKUP(C17,'5a)NDA MPPR'!$B$9:$AK$61,12,FALSE) -> 31.9 | P17: =VLOOKUP(C17,'5a)NDA MPPR'!$B$9:$AK$61,13,FALSE) -> 25.8 | R17: =VLOOKUP(C17,'5a)NDA MPPR'!$B$9:$AK$61,15,FALSE) -> R | S17: =VLOOKUP(C17,'5a)NDA MPPR'!$B$9:$AK$61,16,FALSE) -> 0 | U17: =VLOOKUP(C17,'5a)NDA MPPR'!$B$9:$AK$61,18,FALSE) -> OBC (Mar-25) | W17: =VLOOKUP(C17,'5a)NDA MPPR'!$B$9:$AK$61,20,FALSE) -> 25.979194 | X17: =VLOOKUP(C17,'5a)NDA MPPR'!$B$9:$AK$61,21,FALSE) -> 18.769073 | Y17: =VLOOKUP(C17,'5a)NDA MPPR'!$B$9:$AK$61,22,FALSE) -> -7 | AA17: =VLOOKUP(C17,'5a)NDA MPPR'!$B$9:$AK$61,24,FALSE) -> 45058 | AB17: =VLOOKUP(C17,'5a)NDA MPPR'!$B$9:$AK$61,25,FALSE) -> 46175 | AC17: =VLOOKUP(C17,'5a)NDA MPPR'!$B$9:$AK$61,26,FALSE) -> 0 | AE17: =VLOOKUP(C17,'5a)NDA MPPR'!$B$9:$AK$61,28,FALSE) -> 19.634303 | AF17: =VLOOKUP(C17,'5a)NDA MPPR'!$B$9:$AK$61,29,FALSE) -> 19.634303 | AG17: =VLOOKUP(C17,'5a)NDA MPPR'!$B$9:$AK$61,30,FALSE) -> 16.969073 | AH17: =VLOOKUP(C17,'5a)NDA MPPR'!$B$9:$AK$61,31,FALSE) -> 1.1570639 | AI17: =VLOOKUP(C17,'5a)NDA MPPR'!$B$9:$AK$61,32,FALSE) -> 1 | AJ17: =VLOOKUP(C17,'5a)NDA MPPR'!$B$9:$AK$61,33,FALSE) -> 0.75577028 | AK17: =VLOOKUP(C17,'5a)NDA MPPR'!$B$9:$AK$61,34,FALSE) -> 0.75577029 | AM17: =VLOOKUP(C17,'5a)NDA MPPR'!$B$9:$AK$61,36,FALSE) -> G | AO17: =#REF!-#REF! -> #REF! | AP17: =#REF!-#REF! -> #REF! | AQ17: =#REF!-#REF! -> #REF! | AS17: =#REF!-#REF! -> #REF! | AT17: =#REF!-#REF! -> #REF! | AV17: 25.769102 | AW17: 46175 | AY17: 25.979194 | AZ17: =W17-AY17 -> 0 | BA17: 45058 | BB17: =AA17-BA17 -> 0
A18: =C17 -> Enhanced CNC Airwave System (Encrypted Comms) | B18: =VLOOKUP($C17,'5a)NDA MPPR'!$A$9:$AK$61,2,FALSE) -> The Encrypted Communications (EC) project will deliver the ability for the Civil Nuclear Constabulary (CNC), and other emergency responders utilising current Airwave and/or future Emergency Services Network, to clearly communicate with their Command and Control, both during routine patrols and in emergency response, within a number of identified facilities. The Delivery Confidence Assessment remains Red, since the forecast end date is outside of the Business Case P80 date due to the project currently being on hold pending a future scope delivery decision by the Security & Resilience Programme. The project has to date provided a proven technical infrastructure solution to two initial facilities (which will fully operationalise in late 2025). The decision timeline for further scope delivery has been linked to the production by S&R of Facility Security Plans and their associated Physical Security Vulnerability Assessments (PSVA), since this gives the most robust answer (for both the EC project and the PSVA process) in terms of need. The assessment work on Encrypted Comms project is now complete, resulting in a significant reduction in the project scope. The project EAC has therefore been reduced accordingly. Formal governance steps will conclude during Period 8. The Baseline status is Red, reflective of the current pause. The project has implemented a deferral change control reflecting the impact of the pause to the project; this is within SL delegation and went to the Group Investment Panel (GIC) for noting in late April. Capability and Capacity RAG is Green and it should be noted minimal resource is assigned as the project is on hold.
B20: 35/10137 | C20: Box Encapsulation Plant | D20: Sellafield | F20: =VLOOKUP(C20,'5a)NDA MPPR'!$B$9:$AK$61,3,FALSE) -> A | G20: =VLOOKUP(C20,'5a)NDA MPPR'!$B$9:$AK$61,4,FALSE) -> -1 | I20: =VLOOKUP(C20,'5a)NDA MPPR'!$B$9:$AK$61,6,FALSE) -> FBC (Jul-22) | J20: =VLOOKUP(C20,'5a)NDA MPPR'!$B$9:$AK$61,7,FALSE) -> 1316 | K20: =VLOOKUP(C20,'5a)NDA MPPR'!$B$9:$AK$61,8,FALSE) -> 1512 | L20: =VLOOKUP(C20,'5a)NDA MPPR'!$B$9:$AK$61,9,FALSE) -> 46332 | M20: =VLOOKUP(C20,'5a)NDA MPPR'!$B$9:$AK$61,10,FALSE) -> 46847 | N20: ='3) BC and Sanction'!I97 -> 0 | O20: =VLOOKUP(C20,'5a)NDA MPPR'!$B$9:$AK$61,12,FALSE) -> 1512 | P20: =VLOOKUP(C20,'5a)NDA MPPR'!$B$9:$AK$61,13,FALSE) -> 1389.2 | R20: =VLOOKUP(C20,'5a)NDA MPPR'!$B$9:$AK$61,15,FALSE) -> A | S20: =VLOOKUP(C20,'5a)NDA MPPR'!$B$9:$AK$61,16,FALSE) -> 0 | U20: =VLOOKUP(C20,'5a)NDA MPPR'!$B$9:$AK$61,18,FALSE) -> FBC Re. (Nov-24) | W20: =VLOOKUP(C20,'5a)NDA MPPR'!$B$9:$AK$61,20,FALSE) -> 1335.4604 | X20: =VLOOKUP(C20,'5a)NDA MPPR'!$B$9:$AK$61,21,FALSE) -> 1445.0751 | Y20: =VLOOKUP(C20,'5a)NDA MPPR'!$B$9:$AK$61,22,FALSE) -> 0 | AA20: =VLOOKUP(C20,'5a)NDA MPPR'!$B$9:$AK$61,24,FALSE) -> 46402 | AB20: =VLOOKUP(C20,'5a)NDA MPPR'!$B$9:$AK$61,25,FALSE) -> 46609 | AC20: =VLOOKUP(C20,'5a)NDA MPPR'!$B$9:$AK$61,26,FALSE) -> 0 | AE20: =VLOOKUP(C20,'5a)NDA MPPR'!$B$9:$AK$61,28,FALSE) -> 1268.0733 | AF20: =VLOOKUP(C20,'5a)NDA MPPR'!$B$9:$AK$61,29,FALSE) -> 1213.6179 | AG20: =VLOOKUP(C20,'5a)NDA MPPR'!$B$9:$AK$61,30,FALSE) -> 1338.8089 | AH20: =VLOOKUP(C20,'5a)NDA MPPR'!$B$9:$AK$61,31,FALSE) -> 0.90649081 | AI20: =VLOOKUP(C20,'5a)NDA MPPR'!$B$9:$AK$61,32,FALSE) -> 0.95705662 | AJ20: =VLOOKUP(C20,'5a)NDA MPPR'!$B$9:$AK$61,33,FALSE) -> 0.94954015 | AK20: =VLOOKUP(C20,'5a)NDA MPPR'!$B$9:$AK$61,34,FALSE) -> 0.90876368 | AM20: =VLOOKUP(C20,'5a)NDA MPPR'!$B$9:$AK$61,36,FALSE) -> G | AO20: =T27-G27 -> 0 | AP20: =T27-K27 -> 0 | AQ20: =X27-I27 -> 0 | AS20: =T27-S27 -> 0 | AT20: =X27-W27 -> 0 | AV20: 1445.0751 | AW20: 46609 | AY20: 1335.4604 | AZ20: =W20-AY20 -> 0 | BA20: 46402 | BB20: =AA20-BA20 -> 0
A21: =C20 -> Box Encapsulation Plant | B21: =VLOOKUP($C20,'5a)NDA MPPR'!$A$9:$AK$61,2,FALSE) -> The BEP Project provides the Magnox Swarf Storage Silos (MSSS) Programme the capability to receive, package, inspect, and transfer Intermediate Level Waste to interim stores. At completion, BEP will enable waste retrieval at pace, to maintain an As Low as Reasonably Practicable (ALARP) position, a fundamental requirement of Sellafield Ltd site license conditions. The first project benefit: Regulatory approval to Start Active Commissioning is forecast 10th August 2027. Estimated date for first MSSS box into BEP and Active Commissioning of MSSS waste is November 2027, with benefits realisation associated with the start of Operations April 2028. Project Completion including governance is currently forecast as August 2028, within the period of ‘up to 12 months’ after the Start of Active Commissioning defined in the approved Resubmitted Business Case. The Delivery Confidence Assessment (DCA) has changed to Amber to recognise the Project challenges that are being managed, the Baseline RAG remains Amber. Lifetime EAC is beyond sanction P50 but within sanction P80 cost. The preparation of a P80 Drawdown is underway, targeting executive decisions by end of this calendar year. There is no change in period to the Start Active Commissioning forecast and lifecycle EAC. The project acknowledges pressure on the forecast P50 position following cost growth and schedule slippage in the deterministic Joint Venture (JV) EAC and programme from the impact of Fault Observations (FOBs) on critical path commissioning activities and on-going construction delays impacting the handover of Safety Transfer Certificates (STCs) to commissioning. These delays reflect the projects strategic decision to target more complex STCs first with the majority of these STCs due to be delivered in the coming months. Whilst these delays have resulted in deterministic float erosion and caused a narrowing of the forecasted range (August to November 2027 and £1,445m to £1,475m) confidence remains in delivering within P80 parameters. Highlights in period the handover of 250 STC (WTC Decontamination & Maintenance) from Construction to Commissioning achieved . Grout Plant Engineering Orders (EOs) and Technical Requisitions (TRs) complete. The Capability and Capacity status remains Green this period as the project continues the transition from Construction to Commissioning, with resource transition plans developed.
B23: 35/09592 | C23: Sellafield Product & Residue Store Retreatment Plant | D23: Sellafield | F23: =VLOOKUP(C23,'5a)NDA MPPR'!$B$9:$AK$61,3,FALSE) -> A | G23: =VLOOKUP(C23,'5a)NDA MPPR'!$B$9:$AK$61,4,FALSE) -> -1 | I23: =VLOOKUP(C23,'5a)NDA MPPR'!$B$9:$AK$61,6,FALSE) -> FBC (Jul-21) | J23: =VLOOKUP(C23,'5a)NDA MPPR'!$B$9:$AK$61,7,FALSE) -> 1335.43 | K23: =VLOOKUP(C23,'5a)NDA MPPR'!$B$9:$AK$61,8,FALSE) -> 1673 | L23: =VLOOKUP(C23,'5a)NDA MPPR'!$B$9:$AK$61,9,FALSE) -> 47400 | M23: =VLOOKUP(C23,'5a)NDA MPPR'!$B$9:$AK$61,10,FALSE) -> 48274 | N23: ='3) BC and Sanction'!I106 -> 0 | O23: =VLOOKUP(C23,'5a)NDA MPPR'!$B$9:$AK$61,12,FALSE) -> 1673 | P23: =VLOOKUP(C23,'5a)NDA MPPR'!$B$9:$AK$61,13,FALSE) -> 1482.9 | R23: =VLOOKUP(C23,'5a)NDA MPPR'!$B$9:$AK$61,15,FALSE) -> A | S23: =VLOOKUP(C23,'5a)NDA MPPR'!$B$9:$AK$61,16,FALSE) -> -1 | U23: =VLOOKUP(C23,'5a)NDA MPPR'!$B$9:$AK$61,18,FALSE) -> FBC (Oct-25) | W23: =VLOOKUP(C23,'5a)NDA MPPR'!$B$9:$AK$61,20,FALSE) -> 1479.319 | X23: =VLOOKUP(C23,'5a)NDA MPPR'!$B$9:$AK$61,21,FALSE) -> 1466.5527 | Y23: =VLOOKUP(C23,'5a)NDA MPPR'!$B$9:$AK$61,22,FALSE) -> 0 | AA23: =VLOOKUP(C23,'5a)NDA MPPR'!$B$9:$AK$61,24,FALSE) -> 47574 | AB23: =VLOOKUP(C23,'5a)NDA MPPR'!$B$9:$AK$61,25,FALSE) -> 47574 | AC23: =VLOOKUP(C23,'5a)NDA MPPR'!$B$9:$AK$61,26,FALSE) -> 0 | AE23: =VLOOKUP(C23,'5a)NDA MPPR'!$B$9:$AK$61,28,FALSE) -> 1122.4112 | AF23: =VLOOKUP(C23,'5a)NDA MPPR'!$B$9:$AK$61,29,FALSE) -> 976.10644 | AG23: =VLOOKUP(C23,'5a)NDA MPPR'!$B$9:$AK$61,30,FALSE) -> 1030.0308 | AH23: =VLOOKUP(C23,'5a)NDA MPPR'!$B$9:$AK$61,31,FALSE) -> 0.94764781 | AI23: =VLOOKUP(C23,'5a)NDA MPPR'!$B$9:$AK$61,32,FALSE) -> 0.86965137 | AJ23: =VLOOKUP(C23,'5a)NDA MPPR'!$B$9:$AK$61,33,FALSE) -> 0.75873505 | AK23: =VLOOKUP(C23,'5a)NDA MPPR'!$B$9:$AK$61,34,FALSE) -> 0.65983498 | AM23: =VLOOKUP(C23,'5a)NDA MPPR'!$B$9:$AK$61,36,FALSE) -> A | AO23: =T21-G21 -> 0 | AP23: =T21-K21 -> 0 | AQ23: =X21-I21 -> 0 | AS23: =T21-S21 -> 0 | AT23: =X21-W21 -> 0 | AV23: 1466.5523 | AW23: 47574 | AY23: 1479.319 | AZ23: =W23-AY23 -> -1.0000001e-06 | BA23: 47574 | BB23: =AA23-BA23 -> 0
A24: =C23 -> Sellafield Product & Residue Store Retreatment Plant | B24: =VLOOKUP($C23,'5a)NDA MPPR'!$A$9:$AK$61,2,FALSE) -> The Sellafield Product & Residue Store Retreatment Plant (SRP) project is a key element of the Sellafield Ltd ‘Special Nuclear Materials (SNM) Future State Programme’. The SRP is a complex major project required to provide the capability to receive special nuclear material in existing packages, from existing stores on the Sellafield site, and process the material into a form and package suitable for safe and secure long-term interim storage. The SRO Delivery Confidence Assessment (DCA) has moved from Green to Amber against the P80 cost and schedule from the Full Business Case (FBC) approved by HMG in July 2021. This is primarily reflective of the previously reported emerging issue relating to legislative changes to Passive Fire Protection standards, following the implementation of the Building Safety Act 2022. This Act represents a major regulatory shift in the UK construction industry, particularly in fire safety aiming to improve accountability and safety following the Grenfell Tower Inquiry. The impact of the Passive Fire Protection standards will require a significant amount of engineering design rework and additional installation work in the facility; the main impact is expected to be on the timescales to achieve readiness of the facility for Glove box installation, which has now become the critical path. The initial assessment has been carried out and is currently being quantified and assured and an assessment is also being made as to how this issue should be considered in terms of the projects current P80 sanctioned cost and schedule. Additionally, as previously reported the project has been impacted by extraordinary inflation incurred to date. Following the DESNZ PIC decision in Q2 24/25 to postpone the £164.6m Inflation Sanction relief, the project has had to absorb inflationary costs using its existing contingency. As a result, £128.9m of the P50–P80 sanctioned contingency has been utilised, leaving £190m remaining. This erosion of contingency increases the likelihood of a future re-sanction request for additional P50–P80 funding, particularly as further events may arise that impact the remaining contingency. The project will be requesting P80 cost and schedule relief to DESNZ PIC when appropriate. Key recommendations and actions from the last Gate 0/ Annual Review have been addressed and a review of the effectiveness of the close out actions will be carried out in Quarter 4. These included the requirement to ensure sufficient design engineering resource was in place to support safety case, and mitigation of the risk of delays relating to furnace manufacture (impacting installation of both Glove Boxes and MEICA equipment). The Capability and Capacity RAG status remains Amber with ongoing challenges in recruitment principally across several disciplines including construction, engineering, commissioning, and quality. Finally, the successful active commissioning and future operations of the SRP facility are contingent upon several dependencies managed within the SNM Future State Programme. A critical dependency is the availability of SNM analytical capability, which is essential to support both commissioning and ongoing operational activities. To address this, a dedicated project is being developed and delivered through the PPP to ensure the required analytical capability is in place. The SNM Future State Programme team is responsible for managing all dependencies associated with SRP, with the overarching goal of ensuring that all necessary capabilities are aligned and available to enable the delivery of SRP outcomes and the realisation of associated benefits.
B26: 35/09975 | C26: Security Systems Architecture Upgrade (SSAU) | D26: Sellafield | F26: =VLOOKUP(C26,'5a)NDA MPPR'!$B$9:$AK$61,3,FALSE) -> G | G26: =VLOOKUP(C26,'5a)NDA MPPR'!$B$9:$AK$61,4,FALSE) -> 0 | I26: =VLOOKUP(C26,'5a)NDA MPPR'!$B$9:$AK$61,6,FALSE) -> FBC (Mar-20) | J26: =VLOOKUP(C26,'5a)NDA MPPR'!$B$9:$AK$61,7,FALSE) -> 305.9 | K26: =VLOOKUP(C26,'5a)NDA MPPR'!$B$9:$AK$61,8,FALSE) -> 315.4 | L26: =VLOOKUP(C26,'5a)NDA MPPR'!$B$9:$AK$61,9,FALSE) -> 46053 | M26: =VLOOKUP(C26,'5a)NDA MPPR'!$B$9:$AK$61,10,FALSE) -> 46112 | N26: ='3) BC and Sanction'!I91 -> 0 | O26: =VLOOKUP(C26,'5a)NDA MPPR'!$B$9:$AK$61,12,FALSE) -> 315.4 | P26: =VLOOKUP(C26,'5a)NDA MPPR'!$B$9:$AK$61,13,FALSE) -> 315.4 | R26: =VLOOKUP(C26,'5a)NDA MPPR'!$B$9:$AK$61,15,FALSE) -> R | S26: =VLOOKUP(C26,'5a)NDA MPPR'!$B$9:$AK$61,16,FALSE) -> 0 | U26: =VLOOKUP(C26,'5a)NDA MPPR'!$B$9:$AK$61,18,FALSE) -> FBC (Oct-24) | W26: =VLOOKUP(C26,'5a)NDA MPPR'!$B$9:$AK$61,20,FALSE) -> 297.38168 | X26: =VLOOKUP(C26,'5a)NDA MPPR'!$B$9:$AK$61,21,FALSE) -> 315.08361 | Y26: =VLOOKUP(C26,'5a)NDA MPPR'!$B$9:$AK$61,22,FALSE) -> 0.1 | AA26: =VLOOKUP(C26,'5a)NDA MPPR'!$B$9:$AK$61,24,FALSE) -> 46107 | AB26: =VLOOKUP(C26,'5a)NDA MPPR'!$B$9:$AK$61,25,FALSE) -> 46107 | AC26: =VLOOKUP(C26,'5a)NDA MPPR'!$B$9:$AK$61,26,FALSE) -> 0 | AE26: =VLOOKUP(C26,'5a)NDA MPPR'!$B$9:$AK$61,28,FALSE) -> 292.98492 | AF26: =VLOOKUP(C26,'5a)NDA MPPR'!$B$9:$AK$61,29,FALSE) -> 292.39722 | AG26: =VLOOKUP(C26,'5a)NDA MPPR'!$B$9:$AK$61,30,FALSE) -> 312.99395 | AH26: =VLOOKUP(C26,'5a)NDA MPPR'!$B$9:$AK$61,31,FALSE) -> 0.93419448 | AI26: =VLOOKUP(C26,'5a)NDA MPPR'!$B$9:$AK$61,32,FALSE) -> 0.99799409 | AJ26: =VLOOKUP(C26,'5a)NDA MPPR'!$B$9:$AK$61,33,FALSE) -> 0.9852151 | AK26: =VLOOKUP(C26,'5a)NDA MPPR'!$B$9:$AK$61,34,FALSE) -> 0.98323885 | AM26: =VLOOKUP(C26,'5a)NDA MPPR'!$B$9:$AK$61,36,FALSE) -> A | AO26: =T18-G18 -> 0 | AP26: =T18-K18 -> 0 | AQ26: =X18-I18 -> 0 | AS26: =T18-S18 -> 0 | AT26: =X18-W18 -> 0 | AV26: 314.93422 | AW26: 46107 | AY26: 297.38168 | AZ26: =W26-AY26 -> 0 | BA26: 46107 | BB26: =AA26-BA26 -> 0
A27: =C26 -> Security Systems Architecture Upgrade (SSAU) | B27: =VLOOKUP($C26,'5a)NDA MPPR'!$A$9:$AK$61,2,FALSE) -> The SSAU project will provide infrastructure and equipment that will provide security and emergency response teams with a significantly improved capability to react to and manage security and/or emergency events on the Sellafield site. The first project benefit is equipment which, once operational in the command centre, will provide a significantly improved capability to react and manage security and/or emergency events on the Sellafield site - thereby complying with the standards, expectations and objectives set by nuclear regulators. The Delivery Confidence Assessment remains stable at Green recognising forecast delivery within the Projects P80 Sanction. The Baseline RAG has remained Red in period, as the Cost forecast remains beyond the P50 baseline. The Project is still however forecasting to deliver within the P80 Sanction released to Sellafield. In period the Lifecycle EAC has increased slightly, but still within the P80 Sanction, due to the Level 1 Commissioning Date and Legacy Building Migration moving out slightly from January 2026 to February 2026 due to minor technical issues found in commissioning and impact of the strikes leading to retention of commissioning resources for a further period. In period good progress continues with commissioning with some issues delaying the work as they are resolved, the strike has reduce working time slightly each day but the team are working around this where possible. The next stage of strikes will have an impact as scaffolding is required to access an area of fence which needs minor sensor repairs before commissioning. The Amber rating on the Capability and Capacity RAG recognises that schedule adherence is reliant on skilled resources and the project team is now a very thin layer and any loss of resources would impact delivery.
B29: 35/09968 | C29: CNC Operational Unit | D29: Sellafield | F29: =VLOOKUP(C29,'5a)NDA MPPR'!$B$9:$AK$61,3,FALSE) -> G | G29: =VLOOKUP(C29,'5a)NDA MPPR'!$B$9:$AK$61,4,FALSE) -> 0 | I29: =VLOOKUP(C29,'5a)NDA MPPR'!$B$9:$AK$61,6,FALSE) -> FBC (Jun-24) | J29: =VLOOKUP(C29,'5a)NDA MPPR'!$B$9:$AK$61,7,FALSE) -> 72.6 | K29: =VLOOKUP(C29,'5a)NDA MPPR'!$B$9:$AK$61,8,FALSE) -> 79 | L29: =VLOOKUP(C29,'5a)NDA MPPR'!$B$9:$AK$61,9,FALSE) -> 46106 | M29: =VLOOKUP(C29,'5a)NDA MPPR'!$B$9:$AK$61,10,FALSE) -> 46234 | N29: ='3) BC and Sanction'!I85 -> 0 | O29: =VLOOKUP(C29,'5a)NDA MPPR'!$B$9:$AK$61,12,FALSE) -> 72.6 | P29: =VLOOKUP(C29,'5a)NDA MPPR'!$B$9:$AK$61,13,FALSE) -> 72.6 | R29: =VLOOKUP(C29,'5a)NDA MPPR'!$B$9:$AK$61,15,FALSE) -> G | S29: =VLOOKUP(C29,'5a)NDA MPPR'!$B$9:$AK$61,16,FALSE) -> 0 | U29: =VLOOKUP(C29,'5a)NDA MPPR'!$B$9:$AK$61,18,FALSE) -> FBC (Sep-24) | W29: =VLOOKUP(C29,'5a)NDA MPPR'!$B$9:$AK$61,20,FALSE) -> 72.672543 | X29: =VLOOKUP(C29,'5a)NDA MPPR'!$B$9:$AK$61,21,FALSE) -> 71.079063 | Y29: =VLOOKUP(C29,'5a)NDA MPPR'!$B$9:$AK$61,22,FALSE) -> 0 | AA29: =VLOOKUP(C29,'5a)NDA MPPR'!$B$9:$AK$61,24,FALSE) -> 46106 | AB29: =VLOOKUP(C29,'5a)NDA MPPR'!$B$9:$AK$61,25,FALSE) -> 46106 | AC29: =VLOOKUP(C29,'5a)NDA MPPR'!$B$9:$AK$61,26,FALSE) -> 0 | AE29: =VLOOKUP(C29,'5a)NDA MPPR'!$B$9:$AK$61,28,FALSE) -> 72.6204 | AF29: =VLOOKUP(C29,'5a)NDA MPPR'!$B$9:$AK$61,29,FALSE) -> 64.52305 | AG29: =VLOOKUP(C29,'5a)NDA MPPR'!$B$9:$AK$61,30,FALSE) -> 69.60177 | AH29: =VLOOKUP(C29,'5a)NDA MPPR'!$B$9:$AK$61,31,FALSE) -> 0.92703174 | AI29: =VLOOKUP(C29,'5a)NDA MPPR'!$B$9:$AK$61,32,FALSE) -> 0.88849759 | AJ29: =VLOOKUP(C29,'5a)NDA MPPR'!$B$9:$AK$61,33,FALSE) -> 0.99928249 | AK29: =VLOOKUP(C29,'5a)NDA MPPR'!$B$9:$AK$61,34,FALSE) -> 0.88786008 | AM29: =VLOOKUP(C29,'5a)NDA MPPR'!$B$9:$AK$61,36,FALSE) -> G | AO29: =T24-G24 -> 0 | AP29: =T24-K24 -> 0 | AQ29: =X24-I24 -> 0 | AS29: =T24-S24 -> 0 | AT29: =X24-W24 -> 0 | AV29: 71.086868 | AW29: 46106 | AY29: 72.672543 | AZ29: =W29-AY29 -> 0 | BA29: 46106 | BB29: =AA29-BA29 -> 0
A30: =C29 -> CNC Operational Unit | B30: =VLOOKUP($C29,'5a)NDA MPPR'!$A$9:$AK$61,2,FALSE) -> The Civil Nuclear Constabulary (CNC) Operational Unit project will provide one location on site to house all CNC personnel, with space allowance for future uplift of officers, whilst mitigating health and safety risks associated with the current facilities. The Delivery Confidence Assessment (DCA) is stable at Green as the Resubmission Full Business Case (FBC) has received approval from His Majesty’s Treasury (HMT) in June 2024. Bulk Construction is nearing completion but has been delayed until November, in part due to strike action and reprioritisation of resources to complete critical path works in the Level 1 Board rooms. The completion of the Level 1 Board rooms was initially impacted by the replacement of the non-complaint glands, has been further impacted by the strike action as well as slower than anticipated progress of the other works required to be completed and higher level of snagging than anticipated following contractor and client inspections. These delays have been compounded through the loss of opportunity to recover through additional weekend working due the Union imposed overtime ban related to the on-going industrial action. The completion and commissioning of the Level 1 Boards is the enabler for the release of all future commissioning works. CNSL with support of Amentum Executives, have explored the opportunity to exploit the 120-day duration for Commissioning and Handover, this has seen more efficient planning of the commissioning phase, reducing the duration from 120 days to 93 days to maintain current forecast end date. On-site work continues to progress well, civils scope is focused on external works and building finishes, Control, Electrical & Instrumentation (CE&I) works is focused on ensuring the Level 1 boards are ready for commissioning with the Project working closely with Utilities. Heat, Ventilation and Air Conditioning (HVAC) installation works is almost complete. The Capability and Capacity RAG remains Green for the period with no current vacancies.
B32: 35/07654 | C32: BEPPS2 | D32: Sellafield | F32: =VLOOKUP(C32,'5a)NDA MPPR'!$B$9:$AK$61,3,FALSE) -> G | G32: =VLOOKUP(C32,'5a)NDA MPPR'!$B$9:$AK$61,4,FALSE) -> 0 | I32: =VLOOKUP(C32,'5a)NDA MPPR'!$B$9:$AK$61,6,FALSE) -> OBC (Sep-23) | J32: =VLOOKUP(C32,'5a)NDA MPPR'!$B$9:$AK$61,7,FALSE) -> 776 | K32: =VLOOKUP(C32,'5a)NDA MPPR'!$B$9:$AK$61,8,FALSE) -> 837 | L32: =VLOOKUP(C32,'5a)NDA MPPR'!$B$9:$AK$61,9,FALSE) -> 49490 | M32: =VLOOKUP(C32,'5a)NDA MPPR'!$B$9:$AK$61,10,FALSE) -> 49795 | N32: ='3) BC and Sanction'!I103 -> 0 | O32: =VLOOKUP(C32,'5a)NDA MPPR'!$B$9:$AK$61,12,FALSE) -> 382 | P32: =VLOOKUP(C32,'5a)NDA MPPR'!$B$9:$AK$61,13,FALSE) -> 186 | R32: =VLOOKUP(C32,'5a)NDA MPPR'!$B$9:$AK$61,15,FALSE) -> G | S32: =VLOOKUP(C32,'5a)NDA MPPR'!$B$9:$AK$61,16,FALSE) -> 0 | U32: =VLOOKUP(C32,'5a)NDA MPPR'!$B$9:$AK$61,18,FALSE) -> OBC (Mar-23) | W32: =VLOOKUP(C32,'5a)NDA MPPR'!$B$9:$AK$61,20,FALSE) -> 751.17472 | X32: =VLOOKUP(C32,'5a)NDA MPPR'!$B$9:$AK$61,21,FALSE) -> 749.16803 | Y32: =VLOOKUP(C32,'5a)NDA MPPR'!$B$9:$AK$61,22,FALSE) -> 0 | AA32: =VLOOKUP(C32,'5a)NDA MPPR'!$B$9:$AK$61,24,FALSE) -> 49490 | AB32: =VLOOKUP(C32,'5a)NDA MPPR'!$B$9:$AK$61,25,FALSE) -> 49490 | AC32: =VLOOKUP(C32,'5a)NDA MPPR'!$B$9:$AK$61,26,FALSE) -> 0 | AE32: =VLOOKUP(C32,'5a)NDA MPPR'!$B$9:$AK$61,28,FALSE) -> 120.8995 | AF32: =VLOOKUP(C32,'5a)NDA MPPR'!$B$9:$AK$61,29,FALSE) -> 111.56263 | AG32: =VLOOKUP(C32,'5a)NDA MPPR'!$B$9:$AK$61,30,FALSE) -> 100.76855 | AH32: =VLOOKUP(C32,'5a)NDA MPPR'!$B$9:$AK$61,31,FALSE) -> 1.1071175 | AI32: =VLOOKUP(C32,'5a)NDA MPPR'!$B$9:$AK$61,32,FALSE) -> 0.92277163 | AJ32: =VLOOKUP(C32,'5a)NDA MPPR'!$B$9:$AK$61,33,FALSE) -> 0.16094724 | AK32: =VLOOKUP(C32,'5a)NDA MPPR'!$B$9:$AK$61,34,FALSE) -> 0.14851755 | AM32: =VLOOKUP(C32,'5a)NDA MPPR'!$B$9:$AK$61,36,FALSE) -> G | AO32: =T30-G30 -> 0 | AP32: =T30-K30 -> 0 | AQ32: =X30-I30 -> 0 | AS32: =T30-S30 -> 0 | AT32: =X30-W30 -> 0 | AV32: 749.16803 | AW32: 49490 | AY32: 751.17472 | AZ32: =W32-AY32 -> 0 | BA32: 49490 | BB32: =AA32-BA32 -> 0
A33: =C32 -> BEPPS2 | B33: =VLOOKUP($C32,'5a)NDA MPPR'!$A$9:$AK$61,2,FALSE) -> The Box Encapsulation Plant Product Store 2 (BEPPS2) is a critical enabler for continued high hazard retrievals from the Magnox Swarf Storage Silo (MSSS) and Pile Fuel Cladding Silo (PFCS). It will provide modern, safe and secure long term interim storage for approximately 7,500 packages of Intermediate Level Waste. The strategic requirement has been confirmed. The first project benefit is the ability to receive packages from MSSS and PFCS without constraining hazard reduction programmes. The Senior Responsible Owner (SRO) Delivery Confidence Assessment is Green and the project remains on track against its P50 cost and schedule targets. The project is in the Define Phase, progressing detailed design for transition to civil construction and procurement of long-lead items. The critical path runs through civil construction, mechanical and electrical installation, and commissioning. A sub-critical path flows through the Multi-Disciplinary Design Review (MDDR), which will confirm design maturity and support release of the Outline Business Case (OBC) sanction hold point. The MDDR will be held during Period 8. Engagement with Programme and Project Partnership (PPP) Key Delivery Partners is ongoing to underpin delivery phase planning, cost estimation, and Quantitative Risk Analysis (QRA), informing the Full Business Case (FBC) submission planned for FY2026/27. Site establishment and bulk excavation works are progressing well. The civil construction contract delivery strategy is under review by PPP to ensure value for money. The SPI reflects both historic design delays due to historic resource constraints and the non-utilisation of risk and estimating uncertainty. The forthcoming OBC sanction hold point release submission (January 2026 to IRP & GIC and March 2026 to DESNZ PIC) will include updates on the lifecycle cost estimates that will be underpinned by an updated QRA and will reflect proactive management of opportunities and realisation of threats during the Define Stage. Capability RAG remains Green.
B35: 35/09343 | C35: SIXEP Continuity Plant | D35: Sellafield | F35: =VLOOKUP(C35,'5a)NDA MPPR'!$B$9:$AK$61,3,FALSE) -> G | G35: =VLOOKUP(C35,'5a)NDA MPPR'!$B$9:$AK$61,4,FALSE) -> 0 | I35: =VLOOKUP(C35,'5a)NDA MPPR'!$B$9:$AK$61,6,FALSE) -> FBC (Dec-21) | J35: =VLOOKUP(C35,'5a)NDA MPPR'!$B$9:$AK$61,7,FALSE) -> 1007 | K35: =VLOOKUP(C35,'5a)NDA MPPR'!$B$9:$AK$61,8,FALSE) -> 1182 | L35: =VLOOKUP(C35,'5a)NDA MPPR'!$B$9:$AK$61,9,FALSE) -> 47849 | M35: =VLOOKUP(C35,'5a)NDA MPPR'!$B$9:$AK$61,10,FALSE) -> 48611 | N35: ='3) BC and Sanction'!I109 -> 0 | O35: =VLOOKUP(C35,'5a)NDA MPPR'!$B$9:$AK$61,12,FALSE) -> 1182 | P35: =VLOOKUP(C35,'5a)NDA MPPR'!$B$9:$AK$61,13,FALSE) -> 1150.7 | R35: =VLOOKUP(C35,'5a)NDA MPPR'!$B$9:$AK$61,15,FALSE) -> G | S35: =VLOOKUP(C35,'5a)NDA MPPR'!$B$9:$AK$61,16,FALSE) -> 0 | U35: =VLOOKUP(C35,'5a)NDA MPPR'!$B$9:$AK$61,18,FALSE) -> FBC (Jan-24) | W35: =VLOOKUP(C35,'5a)NDA MPPR'!$B$9:$AK$61,20,FALSE) -> 1133.0636 | X35: =VLOOKUP(C35,'5a)NDA MPPR'!$B$9:$AK$61,21,FALSE) -> 1120.8757 | Y35: =VLOOKUP(C35,'5a)NDA MPPR'!$B$9:$AK$61,22,FALSE) -> 0 | AA35: =VLOOKUP(C35,'5a)NDA MPPR'!$B$9:$AK$61,24,FALSE) -> 48142 | AB35: =VLOOKUP(C35,'5a)NDA MPPR'!$B$9:$AK$61,25,FALSE) -> 48142 | AC35: =VLOOKUP(C35,'5a)NDA MPPR'!$B$9:$AK$61,26,FALSE) -> 0 | AE35: =VLOOKUP(C35,'5a)NDA MPPR'!$B$9:$AK$61,28,FALSE) -> 759.67017 | AF35: =VLOOKUP(C35,'5a)NDA MPPR'!$B$9:$AK$61,29,FALSE) -> 718.60177 | AG35: =VLOOKUP(C35,'5a)NDA MPPR'!$B$9:$AK$61,30,FALSE) -> 744.39202 | AH35: =VLOOKUP(C35,'5a)NDA MPPR'!$B$9:$AK$61,31,FALSE) -> 0.96535394 | AI35: =VLOOKUP(C35,'5a)NDA MPPR'!$B$9:$AK$61,32,FALSE) -> 0.94593918 | AJ35: =VLOOKUP(C35,'5a)NDA MPPR'!$B$9:$AK$61,33,FALSE) -> 0.67045675 | AK35: =VLOOKUP(C35,'5a)NDA MPPR'!$B$9:$AK$61,34,FALSE) -> 0.63421131 | AM35: =VLOOKUP(C35,'5a)NDA MPPR'!$B$9:$AK$61,36,FALSE) -> G | AO35: =T33-G33 -> 0 | AP35: =T33-K33 -> 0 | AQ35: =X33-I33 -> 0 | AS35: =T33-S33 -> 0 | AT35: =X33-W33 -> 0 | AV35: 1120.8916 | AW35: 48142 | AY35: 1133.0636 | AZ35: =W35-AY35 -> 0 | BA35: 48142 | BB35: =AA35-BA35 -> 0
A36: =C35 -> SIXEP Continuity Plant | B36: =VLOOKUP($C35,'5a)NDA MPPR'!$A$9:$AK$61,2,FALSE) -> The SIXEP Continuity Plant (SCP) is required to deliver a continued site effluent treatment capability in support of radioactive liquid effluent discharge permits, fuel pond management, high hazard reduction projects and the overall NDA mission. This project provides a replacement for the existing SIXEP Sea Discharge Treatment plant and is therefore mission critical to the safe operation of the site. The SRO Delivery Confidence Assessment (DCA) currently remains green however there is a significant risk posed by the impact of extraordinary inflation that has been incurred to date. This follows the decision made by PIC in Q2 24/25 to not approve the P80 Inflation Sanction relief for SCP. The NDA have released £108.7m sanction to SL from P80 as an interim measure to deal with the inflation impact, however this substantially erodes the P80 contingency. The first scope driven P80 drawdown for the project has been approved this quarter. Combined, these two drawdowns result in a net £31M P80 contingency remaining. The SRO considers that this is likely to be insufficient for the next 4 years and has submitted a sanction release paper to the Department in September, with review pending. Without this additional sanction the current DCA rating would change from Green to Red, hence this will be kept under review by the SRO throughout 2025/26. From a project performance perspective, the SRO DCA remains Green, echoed by National Infrastructure and Service Transformation Authority (NISTA) Green rating received in June 25/26. The Baseline RAG remains Green. Fabrication of off-site pipework planned for completion Q4 25/26. Site pipework and vessel install is progressing well in both the Effluent Treatment Cell (ETC) and Bulk Storage Tank (BST) cells. Both halves of the reception pumping tank now in position and welding has commenced within the ETC, marking another significant milestone for the project. marking another milestone for the project. Works continue to progress across all floors within the Service Building prior to handover over to Mechanical, Electrical, Instrumentation, Control & Automation (MEICA) trades. Bulk Storage Tanks – welding of the first tank continues to progress in cell. Project Wide Objectives - PWO4 - Handover of BST cell to Commissioning, PWO5 - Handover Services Building to Commissioning and PWO6 - Handover of ETC to Commissioning are all currently forecasting to be delayed with further impending strike action (Industrial Relations issues) however, these are not a threat to the critical path and project remains within P50. The last milestone on the journey is commencement of active commissioning (licence instrument approvals). Post scope driven P80 drawdown impact the baseline date is now 22nd July 2030 (P50) along with the P50 Lifecycle baseline end date moving to 21st October 2031. The forecast dates and lifecycle EAC remain stable. The Capability and Capacity RAG remains Green with no issues to report.
B38: 35/10417 | C38: ILW East Land Excavation | D38: Sellafield | F38: =VLOOKUP(C38,'5a)NDA MPPR'!$B$9:$AK$61,3,FALSE) -> G | G38: =VLOOKUP(C38,'5a)NDA MPPR'!$B$9:$AK$61,4,FALSE) -> 0 | I38: =VLOOKUP(C38,'5a)NDA MPPR'!$B$9:$AK$61,6,FALSE) -> FBC (Jun-24) | J38: =VLOOKUP(C38,'5a)NDA MPPR'!$B$9:$AK$61,7,FALSE) -> 69.1 | K38: =VLOOKUP(C38,'5a)NDA MPPR'!$B$9:$AK$61,8,FALSE) -> 75.8 | L38: =VLOOKUP(C38,'5a)NDA MPPR'!$B$9:$AK$61,9,FALSE) -> 46295 | M38: =VLOOKUP(C38,'5a)NDA MPPR'!$B$9:$AK$61,10,FALSE) -> 46446 | N38: ='3) BC and Sanction'!I112 -> 0 | O38: =VLOOKUP(C38,'5a)NDA MPPR'!$B$9:$AK$61,12,FALSE) -> n/a | P38: =VLOOKUP(C38,'5a)NDA MPPR'!$B$9:$AK$61,13,FALSE) -> 69.1 | R38: =VLOOKUP(C38,'5a)NDA MPPR'!$B$9:$AK$61,15,FALSE) -> G | S38: =VLOOKUP(C38,'5a)NDA MPPR'!$B$9:$AK$61,16,FALSE) -> 0 | U38: =VLOOKUP(C38,'5a)NDA MPPR'!$B$9:$AK$61,18,FALSE) -> FBC (Mar-23) | W38: =VLOOKUP(C38,'5a)NDA MPPR'!$B$9:$AK$61,20,FALSE) -> 67.414678 | X38: =VLOOKUP(C38,'5a)NDA MPPR'!$B$9:$AK$61,21,FALSE) -> 35.500379 | Y38: =VLOOKUP(C38,'5a)NDA MPPR'!$B$9:$AK$61,22,FALSE) -> 0 | AA38: =VLOOKUP(C38,'5a)NDA MPPR'!$B$9:$AK$61,24,FALSE) -> 46266 | AB38: =VLOOKUP(C38,'5a)NDA MPPR'!$B$9:$AK$61,25,FALSE) -> 46112 | AC38: =VLOOKUP(C38,'5a)NDA MPPR'!$B$9:$AK$61,26,FALSE) -> 0 | AE38: =VLOOKUP(C38,'5a)NDA MPPR'!$B$9:$AK$61,28,FALSE) -> 61.06499 | AF38: =VLOOKUP(C38,'5a)NDA MPPR'!$B$9:$AK$61,29,FALSE) -> 60.119926 | AG38: =VLOOKUP(C38,'5a)NDA MPPR'!$B$9:$AK$61,30,FALSE) -> 35.120399 | AH38: =VLOOKUP(C38,'5a)NDA MPPR'!$B$9:$AK$61,31,FALSE) -> 1.7118235 | AI38: =VLOOKUP(C38,'5a)NDA MPPR'!$B$9:$AK$61,32,FALSE) -> 0.98452362 | AJ38: =VLOOKUP(C38,'5a)NDA MPPR'!$B$9:$AK$61,33,FALSE) -> 0.9058115 | AK38: =VLOOKUP(C38,'5a)NDA MPPR'!$B$9:$AK$61,34,FALSE) -> 0.89179282 | AM38: =VLOOKUP(C38,'5a)NDA MPPR'!$B$9:$AK$61,36,FALSE) -> G | AO38: =T36-G36 -> 0 | AP38: =T36-K36 -> 0 | AQ38: =X36-I36 -> 0 | AS38: =T36-S36 -> 0 | AT38: =X36-W36 -> 0 | AV38: 35.50088 | AW38: 46112 | AY38: 67.414678 | AZ38: =W38-AY38 -> 0 | BA38: 46266 | BB38: =AA38-BA38 -> 0
A39: =C38 -> ILW East Land Excavation | B39: =VLOOKUP($C38,'5a)NDA MPPR'!$A$9:$AK$61,2,FALSE) -> The ILW EZ Phase 1 Excavation Project is a key enabler to allow the future major project Lightly Shielded Store 1 (LSS1) to commence construction and also de-risks LSS1 construction. The delays in issuing the Service Commencement Notification (SCN) and late Pre-Construction Information (PCI) caused a 4-month delay to the beginning of delivery, however the excavation work has now recovered. The first project benefit: This project delivers a number of benefits, both direct as a key enabler for LSS1, and indirect in adopting an Enterprise approach to zonal development. The Baseline remains green. All issues have now been rectified. All works are now complete and awaiting isolations to be removed before sign off. Walk rounds have taken place and a meeting to arrange the CTC transfer is being set up. Lifecycle EAC and the forecast date for close out of the Project remain stable. The Capability and Capacity RAG remains Green.
